Workbook

Sheet Distribution
A1: Exp Level | B1: (Multiple Items)
A3: Count of Job Title | B3: Column Labels
A4: Row Labels | B4: Data Analyst | C4: Data Engineer | D4: Data Scientist | E4: Director/VP | F4: DS Manager | G4: ML Engineer | H4: Research Scientist | I4: Grand Total
A5: $100–125K | B5: 3 | C5: 17 | D5: 33 | G5: 4 | H5: 3 | I5: 60
A6: $125–150K | B6: 2 | C6: 7 | D6: 46 | E6: 2 | G6: 2 | H6: 1 | I6: 60
A7: $50–75K | B7: 14 | C7: 2 | D7: 9 | G7: 2 | H7: 4 | I7: 31
A8: $75–100K | B8: 7 | C8: 7 | D8: 28 | G8: 3 | H8: 1 | I8: 46
A9: <$50K | B9: 9 | I9: 9
A10: >$150K | C10: 9 | D10: 31 | F10: 2 | G10: 1 | H10: 1 | I10: 44
A11: Grand Total | B11: 35 | C11: 42 | D11: 147 | E11: 2 | F11: 2 | G11: 12 | H11: 10 | I11: 250

Sheet data_cleaned_2021
A1: Job Title | B1: Exp Level | C1: Job Category | D1: Rating | E1: Location | F1: City | G1: Size | H1: Industry | I1: Lower Salary(in K) | J1: Upper Salary(in K ) | K1: Avg Salary(K) | L1: Salary Range | M1: Age
A2: Data Scientist | B2: =IF(OR(ISNUMBER(SEARCH("Senior",A2)),ISNUMBER(SEARCH("Sr",A2)),ISNUMBER(SEARCH("Lead",A2)),ISNUMBER(SEARCH("Principal",A2))),"Senior",IF(OR(ISNUMBER(SEARCH("Junior",A2)),ISNUMBER(SEARCH("Jr",A2)),ISNUMBER(SEARCH("Entry",A2)),ISNUMBER(SEARCH("Associate",A2))),"Junior",IF(OR(ISNUMBER(SEARCH("Manager",A2)),ISNUMBER(SEARCH("Director",A2)),ISNUMBER(SEARCH("Head",A2)),ISNUMBER(SEARCH("VP",A2))),"Management","Mid-Level"))) -> Mid-Level | C2: =IF(ISNUMBER(SEARCH("Machine Learn",A2)),"ML Engineer",IF(ISNUMBER(SEARCH("Data Engineer",A2)),"Data Engineer",IF(ISNUMBER(SEARCH("Data Analyst",A2)),"Data Analyst",IF(ISNUMBER(SEARCH("Business Analyst",A2)),"Business Analyst",IF(ISNUMBER(SEARCH("Research",A2)),"Research Scientist",IF(ISNUMBER(SEARCH("Manager",A2)),"DS Manager",IF(ISNUMBER(SEARCH("Director",A2)),"Director/VP","Data Scientist"))))))) -> Data Scientist | D2: 3.8 | E2: Albuquerque, NM | F2: =IFERROR(LEFT(E2, FIND(",", E2)-1), E2) -> Albuquerque | G2: 501 - 1000 | H2: Aerospace & Defense | I2: 53 | J2: 91 | K2: 72 | L2: =IF(K2<50,"<$50K",IF(K2<75,"$50–75K",IF(K2<100,"$75–100K",IF(K2<125,"$100–125K",IF(K2<150,"$125–150K",">$150K"))))) -> $50–75K | M2: 48
A3: Healthcare Data Scientist | B3: =IF(OR(ISNUMBER(SEARCH("Senior",A3)),ISNUMBER(SEARCH("Sr",A3)),ISNUMBER(SEARCH("Lead",A3)),ISNUMBER(SEARCH("Principal",A3))),"Senior",IF(OR(ISNUMBER(SEARCH("Junior",A3)),ISNUMBER(SEARCH("Jr",A3)),ISNUMBER(SEARCH("Entry",A3)),ISNUMBER(SEARCH("Associate",A3))),"Junior",IF(OR(ISNUMBER(SEARCH("Manager",A3)),ISNUMBER(SEARCH("Director",A3)),ISNUMBER(SEARCH("Head",A3)),ISNUMBER(SEARCH("VP",A3))),"Management","Mid-Level"))) -> Mid-Level | C3: =IF(ISNUMBER(SEARCH("Machine Learn",A3)),"ML Engineer",IF(ISNUMBER(SEARCH("Data Engineer",A3)),"Data Engineer",IF(ISNUMBER(SEARCH("Data Analyst",A3)),"Data Analyst",IF(ISNUMBER(SEARCH("Business Analyst",A3)),"Business Analyst",IF(ISNUMBER(SEARCH("Research",A3)),"Research Scientist",IF(ISNUMBER(SEARCH("Manager",A3)),"DS Manager",IF(ISNUMBER(SEARCH("Director",A3)),"Director/VP","Data Scientist"))))))) -> Data Scientist | D3: 3.4 | E3: Linthicum, MD | F3: =IFERROR(LEFT(E3, FIND(",", E3)-1), E3) -> Linthicum | G3: 10000+ | H3: Health Care Services & Hospitals | I3: 63 | J3: 112 | K3: 87.5 | L3: =IF(K3<50,"<$50K",IF(K3<75,"$50–75K",IF(K3<100,"$75–100K",IF(K3<125,"$100–125K",IF(K3<150,"$125–150K",">$150K"))))) -> $75–100K | M3: 37
A4: Data Scientist | B4: =IF(OR(ISNUMBER(SEARCH("Senior",A4)),ISNUMBER(SEARCH("Sr",A4)),ISNUMBER(SEARCH("Lead",A4)),ISNUMBER(SEARCH("Principal",A4))),"Senior",IF(OR(ISNUMBER(SEARCH("Junior",A4)),ISNUMBER(SEARCH("Jr",A4)),ISNUMBER(SEARCH("Entry",A4)),ISNUMBER(SEARCH("Associate",A4))),"Junior",IF(OR(ISNUMBER(SEARCH("Manager",A4)),ISNUMBER(SEARCH("Director",A4)),ISNUMBER(SEARCH("Head",A4)),ISNUMBER(SEARCH("VP",A4))),"Management","Mid-Level"))) -> Mid-Level | C4: =IF(ISNUMBER(SEARCH("Machine Learn",A4)),"ML Engineer",IF(ISNUMBER(SEARCH("Data Engineer",A4)),"Data Engineer",IF(ISNUMBER(SEARCH("Data Analyst",A4)),"Data Analyst",IF(ISNUMBER(SEARCH("Business Analyst",A4)),"Business Analyst",IF(ISNUMBER(SEARCH("Research",A4)),"Research Scientist",IF(ISNUMBER(SEARCH("Manager",A4)),"DS Manager",IF(ISNUMBER(SEARCH("Director",A4)),"Director/VP","Data Scientist"))))))) -> Data Scientist | D4: 4.8 | E4: Clearwater, FL | F4: =IFERROR(LEFT(E4, FIND(",", E4)-1), E4) -> Clearwater | G4: 501 - 1000 | H4: Security Services | I4: 80 | J4: 90 | K4: 85 | L4: =IF(K4<50,"<$50K",IF(K4<75,"$50–75K",IF(K4<100,"$75–100K",IF(K4<125,"$100–125K",IF(K4<150,"$125–150K",">$150K"))))) -> $75–100K | M4: 11
A5: Data Scientist | B5: =IF(OR(ISNUMBER(SEARCH("Senior",A5)),ISNUMBER(SEARCH("Sr",A5)),ISNUMBER(SEARCH("Lead",A5)),ISNUMBER(SEARCH("Principal",A5))),"Senior",IF(OR(ISNUMBER(SEARCH("Junior",A5)),ISNUMBER(SEARCH("Jr",A5)),ISNUMBER(SEARCH("Entry",A5)),ISNUMBER(SEARCH("Associate",A5))),"Junior",IF(OR(ISNUMBER(SEARCH("Manager",A5)),ISNUMBER(SEARCH("Director",A5)),ISNUMBER(SEARCH("Head",A5)),ISNUMBER(SEARCH("VP",A5))),"Management","Mid-Level"))) -> Mid-Level | C5: =IF(ISNUMBER(SEARCH("Machine Learn",A5)),"ML Engineer",IF(ISNUMBER(SEARCH("Data Engineer",A5)),"Data Engineer",IF(ISNUMBER(SEARCH("Data Analyst",A5)),"Data Analyst",IF(ISNUMBER(SEARCH("Business Analyst",A5)),"Business Analyst",IF(ISNUMBER(SEARCH("Research",A5)),"Research Scientist",IF(ISNUMBER(SEARCH("Manager",A5)),"DS Manager",IF(ISNUMBER(SEARCH("Director",A5)),"Director/VP","Data Scientist"))))))) -> Data Scientist | D5: 3.8 | E5: Richland, WA | F5: =IFERROR(LEFT(E5, FIND(",", E5)-1), E5) -> Richland | G5: 1001 - 5000 | H5: Energy | I5: 56 | J5: 97 | K5: 76.5 | L5: =IF(K5<50,"<$50K",IF(K5<75,"$50–75K",IF(K5<100,"$75–100K",IF(K5<125,"$100–125K",IF(K5<150,"$125–150K",">$150K"))))) -> $75–100K | M5: 56
A6: Data Scientist | B6: =IF(OR(ISNUMBER(SEARCH("Senior",A6)),ISNUMBER(SEARCH("Sr",A6)),ISNUMBER(SEARCH("Lead",A6)),ISNUMBER(SEARCH("Principal",A6))),"Senior",IF(OR(ISNUMBER(SEARCH("Junior",A6)),ISNUMBER(SEARCH("Jr",A6)),ISNUMBER(SEARCH("Entry",A6)),ISNUMBER(SEARCH("Associate",A6))),"Junior",IF(OR(ISNUMBER(SEARCH("Manager",A6)),ISNUMBER(SEARCH("Director",A6)),ISNUMBER(SEARCH("Head",A6)),ISNUMBER(SEARCH("VP",A6))),"Management","Mid-Level"))) -> Mid-Level | C6: =IF(ISNUMBER(SEARCH("Machine Learn",A6)),"ML Engineer",IF(ISNUMBER(SEARCH("Data Engineer",A6)),"Data Engineer",IF(ISNUMBER(SEARCH("Data Analyst",A6)),"Data Analyst",IF(ISNUMBER(SEARCH("Business Analyst",A6)),"Business Analyst",IF(ISNUMBER(SEARCH("Research",A6)),"Research Scientist",IF(ISNUMBER(SEARCH("Manager",A6)),"DS Manager",IF(ISNUMBER(SEARCH("Director",A6)),"Director/VP","Data Scientist"))))))) -> Data Scientist | D6: 2.9 | E6: New York, NY | F6: =IFERROR(LEFT(E6, FIND(",", E6)-1), E6) -> New York | G6: 51 - 200 | H6: Advertising & Marketing | I6: 86 | J6: 143 | K6: 114.5 | L6: =IF(K6<50,"<$50K",IF(K6<75,"$50–75K",IF(K6<100,"$75–100K",IF(K6<125,"$100–125K",IF(K6<150,"$125–150K",">$150K"))))) -> $100–125K | M6: 23
A7: Data Scientist | B7: =IF(OR(ISNUMBER(SEARCH("Senior",A7)),ISNUMBER(SEARCH("Sr",A7)),ISNUMBER(SEARCH("Lead",A7)),ISNUMBER(SEARCH("Principal",A7))),"Senior",IF(OR(ISNUMBER(SEARCH("Junior",A7)),ISNUMBER(SEARCH("Jr",A7)),ISNUMBER(SEARCH("Entry",A7)),ISNUMBER(SEARCH("Associate",A7))),"Junior",IF(OR(ISNUMBER(SEARCH("Manager",A7)),ISNUMBER(SEARCH("Director",A7)),ISNUMBER(SEARCH("Head",A7)),ISNUMBER(SEARCH("VP",A7))),"Management","Mid-Level"))) -> Mid-Level | C7: =IF(ISNUMBER(SEARCH("Machine Learn",A7)),"ML Engineer",IF(ISNUMBER(SEARCH("Data Engineer",A7)),"Data Engineer",IF(ISNUMBER(SEARCH("Data Analyst",A7)),"Data Analyst",IF(ISNUMBER(SEARCH("Business Analyst",A7)),"Business Analyst",IF(ISNUMBER(SEARCH("Research",A7)),"Research Scientist",IF(ISNUMBER(SEARCH("Manager",A7)),"DS Manager",IF(ISNUMBER(SEARCH("Director",A7)),"Director/VP","Data Scientist"))))))) -> Data Scientist | D7: 3.4 | E7: Dallas, TX | F7: =IFERROR(LEFT(E7, FIND(",", E7)-1), E7) -> Dallas | G7: 201 - 500 | H7: Real Estate | I7: 71 | J7: 119 | K7: 95 | L7: =IF(K7<50,"<$50K",IF(K7<75,"$50–75K",IF(K7<100,"$75–100K",IF(K7<125,"$100–125K",IF(K7<150,"$125–150K",">$150K"))))) -> $75–100K | M7: 21
A8: Data Scientist | B8: =IF(OR(ISNUMBER(SEARCH("Senior",A8)),ISNUMBER(SEARCH("Sr",A8)),ISNUMBER(SEARCH("Lead",A8)),ISNUMBER(SEARCH("Principal",A8))),"Senior",IF(OR(ISNUMBER(SEARCH("Junior",A8)),ISNUMBER(SEARCH("Jr",A8)),ISNUMBER(SEARCH("Entry",A8)),ISNUMBER(SEARCH("Associate",A8))),"Junior",IF(OR(ISNUMBER(SEARCH("Manager",A8)),ISNUMBER(SEARCH("Director",A8)),ISNUMBER(SEARCH("Head",A8)),ISNUMBER(SEARCH("VP",A8))),"Management","Mid-Level"))) -> Mid-Level | C8: =IF(ISNUMBER(SEARCH("Machine Learn",A8)),"ML Engineer",IF(ISNUMBER(SEARCH("Data Engineer",A8)),"Data Engineer",IF(ISNUMBER(SEARCH("Data Analyst",A8)),"Data Analyst",IF(ISNUMBER(SEARCH("Business Analyst",A8)),"Business Analyst",IF(ISNUMBER(SEARCH("Research",A8)),"Research Scientist",IF(ISNUMBER(SEARCH("Manager",A8)),"DS Manager",IF(ISNUMBER(SEARCH("Director",A8)),"Director/VP","Data Scientist"))))))) -> Data Scientist | D8: 4.1 | E8: Baltimore, MD | F8: =IFERROR(LEFT(E8, FIND(",", E8)-1), E8) -> Baltimore | G8: 501 - 1000 | H8: Banks & Credit Unions | I8: 54 | J8: 93 | K8: 73.5 | L8: =IF(K8<50,"<$50K",IF(K8<75,"$50–75K",IF(K8<100,"$75–100K",IF(K8<125,"$100–125K",IF(K8<150,"$125–150K",">$150K"))))) -> $50–75K | M8: 13
A9: Data Scientist | B9: =IF(OR(ISNUMBER(SEARCH("Senior",A9)),ISNUMBER(SEARCH("Sr",A9)),ISNUMBER(SEARCH("Lead",A9)),ISNUMBER(SEARCH("Principal",A9))),"Senior",IF(OR(ISNUMBER(SEARCH("Junior",A9)),ISNUMBER(SEARCH("Jr",A9)),ISNUMBER(SEARCH("Entry",A9)),ISNUMBER(SEARCH("Associate",A9))),"Junior",IF(OR(ISNUMBER(SEARCH("Manager",A9)),ISNUMBER(SEARCH("Director",A9)),ISNUMBER(SEARCH("Head",A9)),ISNUMBER(SEARCH("VP",A9))),"Management","Mid-Level"))) -> Mid-Level | C9: =IF(ISNUMBER(SEARCH("Machine Learn",A9)),"ML Engineer",IF(ISNUMBER(SEARCH("Data Engineer",A9)),"Data Engineer",IF(ISNUMBER(SEARCH("Data Analyst",A9)),"Data Analyst",IF(ISNUMBER(SEARCH("Business Analyst",A9)),"Business Analyst",IF(ISNUMBER(SEARCH("Research",A9)),"Research Scientist",IF(ISNUMBER(SEARCH("Manager",A9)),"DS Manager",IF(ISNUMBER(SEARCH("Director",A9)),"Director/VP","Data Scientist"))))))) -> Data Scientist | D9: 3.8 | E9: San Jose, CA | F9: =IFERROR(LEFT(E9, FIND(",", E9)-1), E9) -> San Jose | G9: 201 - 500 | H9: Consulting | I9: 86 | J9: 142 | K9: 114 | L9: =IF(K9<50,"<$50K",IF(K9<75,"$50–75K",IF(K9<100,"$75–100K",IF(K9<125,"$100–125K",IF(K9<150,"$125–150K",">$150K"))))) -> $100–125K | M9: 16
A10: Research Scientist | B10: =IF(OR(ISNUMBER(SEARCH("Senior",A10)),ISNUMBER(SEARCH("Sr",A10)),ISNUMBER(SEARCH("Lead",A10)),ISNUMBER(SEARCH("Principal",A10))),"Senior",IF(OR(ISNUMBER(SEARCH("Junior",A10)),ISNUMBER(SEARCH("Jr",A10)),ISNUMBER(SEARCH("Entry",A10)),ISNUMBER(SEARCH("Associate",A10))),"Junior",IF(OR(ISNUMBER(SEARCH("Manager",A10)),ISNUMBER(SEARCH("Director",A10)),ISNUMBER(SEARCH("Head",A10)),ISNUMBER(SEARCH("VP",A10))),"Management","Mid-Level"))) -> Mid-Level | C10: =IF(ISNUMBER(SEARCH("Machine Learn",A10)),"ML Engineer",IF(ISNUMBER(SEARCH("Data Engineer",A10)),"Data Engineer",IF(ISNUMBER(SEARCH("Data Analyst",A10)),"Data Analyst",IF(ISNUMBER(SEARCH("Business Analyst",A10)),"Business Analyst",IF(ISNUMBER(SEARCH("Research",A10)),"Research Scientist",IF(ISNUMBER(SEARCH("Manager",A10)),"DS Manager",IF(ISNUMBER(SEARCH("Director",A10)),"Director/VP","Data Scientist"))))))) -> Research Scientist | D10: 3.3 | E10: Rochester, NY | F10: =IFERROR(LEFT(E10, FIND(",", E10)-1), E10) -> Rochester | G10: 10000+ | H10: Health Care Services & Hospitals | I10: 38 | J10: 84 | K10: 61 | L10: =IF(K10<50,"<$50K",IF(K10<75,"$50–75K",IF(K10<100,"$75–100K",IF(K10<125,"$100–125K",IF(K10<150,"$125–150K",">$150K"))))) -> $50–75K | M10: 7
A11: Data Scientist | B11: =IF(OR(ISNUMBER(SEARCH("Senior",A11)),ISNUMBER(SEARCH("Sr",A11)),ISNUMBER(SEARCH("Lead",A11)),ISNUMBER(SEARCH("Principal",A11))),"Senior",IF(OR(ISNUMBER(SEARCH("Junior",A11)),ISNUMBER(SEARCH("Jr",A11)),ISNUMBER(SEARCH("Entry",A11)),ISNUMBER(SEARCH("Associate",A11))),"Junior",IF(OR(ISNUMBER(SEARCH("Manager",A11)),ISNUMBER(SEARCH("Director",A11)),ISNUMBER(SEARCH("Head",A11)),ISNUMBER(SEARCH("VP",A11))),"Management","Mid-Level"))) -> Mid-Level | C11: =IF(ISNUMBER(SEARCH("Machine Learn",A11)),"ML Engineer",IF(ISNUMBER(SEARCH("Data Engineer",A11)),"Data Engineer",IF(ISNUMBER(SEARCH("Data Analyst",A11)),"Data Analyst",IF(ISNUMBER(SEARCH("Business Analyst",A11)),"Business Analyst",IF(ISNUMBER(SEARCH("Research",A11)),"Research Scientist",IF(ISNUMBER(SEARCH("Manager",A11)),"DS Manager",IF(ISNUMBER(SEARCH("Director",A11)),"Director/VP","Data Scientist"))))))) -> Data Scientist | D11: 4.6 | E11: New York, NY | F11: =IFERROR(LEFT(E11, FIND(",", E11)-1), E11) -> New York | G11: 51 - 200 | H11: Internet | I11: 120 | J11: 160 | K11: 140 | L11: =IF(K11<50,"<$50K",IF(K11<75,"$50–75K",IF(K11<100,"$75–100K",IF(K11<125,"$100–125K",IF(K11<150,"$125–150K",">$150K"))))) -> $125–150K | M11: 12
A12: Data Scientist | B12: =IF(OR(ISNUMBER(SEARCH("Senior",A12)),ISNUMBER(SEARCH("Sr",A12)),ISNUMBER(SEARCH("Lead",A12)),ISNUMBER(SEARCH("Principal",A12))),"Senior",IF(OR(ISNUMBER(SEARCH("Junior",A12)),ISNUMBER(SEARCH("Jr",A12)),ISNUMBER(SEARCH("Entry",A12)),ISNUMBER(SEARCH("Associate",A12))),"Junior",IF(OR(ISNUMBER(SEARCH("Manager",A12)),ISNUMBER(SEARCH("Director",A12)),ISNUMBER(SEARCH("Head",A12)),ISNUMBER(SEARCH("VP",A12))),"Management","Mid-Level"))) -> Mid-Level | C12: =IF(ISNUMBER(SEARCH("Machine Learn",A12)),"ML Engineer",IF(ISNUMBER(SEARCH("Data Engineer",A12)),"Data Engineer",IF(ISNUMBER(SEARCH("Data Analyst",A12)),"Data Analyst",IF(ISNUMBER(SEARCH("Business Analyst",A12)),"Business Analyst",IF(ISNUMBER(SEARCH("Research",A12)),"Research Scientist",IF(ISNUMBER(SEARCH("Manager",A12)),"DS Manager",IF(ISNUMBER(SEARCH("Director",A12)),"Director/VP","Data Scientist"))))))) -> Data Scientist | D12: 3.5 | E12: San Jose, CA | F12: =IFERROR(LEFT(E12, FIND(",", E12)-1), E12) -> San Jose | G12: 501 - 1000 | H12: Other Retail Stores | I12: 126 | J12: 201 | K12: 163.5 | L12: =IF(K12<50,"<$50K",IF(K12<75,"$50–75K",IF(K12<100,"$75–100K",IF(K12<125,"$100–125K",IF(K12<150,"$125–150K",">$150K"))))) -> >$150K | M12: 10
A13: Data Scientist | B13: =IF(OR(ISNUMBER(SEARCH("Senior",A13)),ISNUMBER(SEARCH("Sr",A13)),ISNUMBER(SEARCH("Lead",A13)),ISNUMBER(SEARCH("Principal",A13))),"Senior",IF(OR(ISNUMBER(SEARCH("Junior",A13)),ISNUMBER(SEARCH("Jr",A13)),ISNUMBER(SEARCH("Entry",A13)),ISNUMBER(SEARCH("Associate",A13))),"Junior",IF(OR(ISNUMBER(SEARCH("Manager",A13)),ISNUMBER(SEARCH("Director",A13)),ISNUMBER(SEARCH("Head",A13)),ISNUMBER(SEARCH("VP",A13))),"Management","Mid-Level"))) -> Mid-Level | C13: =IF(ISNUMBER(SEARCH("Machine Learn",A13)),"ML Engineer",IF(ISNUMBER(SEARCH("Data Engineer",A13)),"Data Engineer",IF(ISNUMBER(SEARCH("Data Analyst",A13)),"Data Analyst",IF(ISNUMBER(SEARCH("Business Analyst",A13)),"Business Analyst",IF(ISNUMBER(SEARCH("Research",A13)),"Research Scientist",IF(ISNUMBER(SEARCH("Manager",A13)),"DS Manager",IF(ISNUMBER(SEARCH("Director",A13)),"Director/VP","Data Scientist"))))))) -> Data Scientist | D13: 4.1 | E13: Chantilly, VA | F13: =IFERROR(LEFT(E13, FIND(",", E13)-1), E13) -> Chantilly | G13: 5001 - 10000 | H13: Research & Development | I13: 64 | J13: 106 | K13: 85 | L13: =IF(K13<50,"<$50K",IF(K13<75,"$50–75K",IF(K13<100,"$75–100K",IF(K13<125,"$100–125K",IF(K13<150,"$125–150K",">$150K"))))) -> $75–100K | M13: 53
... A42: Data Analyst | B42: =IF(OR(ISNUMBER(SEARCH("Senior",A42)),ISNUMBER(SEARCH("Sr",A42)),ISNUMBER(SEARCH("Lead",A42)),ISNUMBER(SEARCH("Principal",A42))),"Senior",IF(OR(ISNUMBER(SEARCH("Junior",A42)),ISNUMBER(SEARCH("Jr",A42)),ISNUMBER(SEARCH("Entry",A42)),ISNUMBER(SEARCH("Associate",A42))),"Junior",IF(OR(ISNUMBER(SEARCH("Manager",A42)),ISNUMBER(SEARCH("Director",A42)),ISNUMBER(SEARCH("Head",A42)),ISNUMBER(SEARCH("VP",A42))),"Management","Mid-Level"))) -> Mid-Level | C42: =IF(ISNUMBER(SEARCH("Machine Learn",A42)),"ML Engineer",IF(ISNUMBER(SEARCH("Data Engineer",A42)),"Data Engineer",IF(ISNUMBER(SEARCH("Data Analyst",A42)),"Data Analyst",IF(ISNUMBER(SEARCH("Business Analyst",A42)),"Business Analyst",IF(ISNUMBER(SEARCH("Research",A42)),"Research Scientist",IF(ISNUMBER(SEARCH("Manager",A42)),"DS Manager",IF(ISNUMBER(SEARCH("Director",A42)),"Director/VP","Data Scientist"))))))) -> Data Analyst | D42: 4.2 | E42: San Francisco, CA | F42: =IFERROR(LEFT(E42, FIND(",", E42)-1), E42) -> San Francisco | G42: 201 - 500 | H42: IT Services | I42: 64 | J42: 112 | K42: 88 | L42: =IF(K42<50,"<$50K",IF(K42<75,"$50–75K",IF(K42<100,"$75–100K",IF(K42<125,"$100–125K",IF(K42<150,"$125–150K",">$150K"))))) -> $75–100K | M42: 13
A43: Data Engineer | B43: =IF(OR(ISNUMBER(SEARCH("Senior",A43)),ISNUMBER(SEARCH("Sr",A43)),ISNUMBER(SEARCH("Lead",A43)),ISNUMBER(SEARCH("Principal",A43))),"Senior",IF(OR(ISNUMBER(SEARCH("Junior",A43)),ISNUMBER(SEARCH("Jr",A43)),ISNUMBER(SEARCH("Entry",A43)),ISNUMBER(SEARCH("Associate",A43))),"Junior",IF(OR(ISNUMBER(SEARCH("Manager",A43)),ISNUMBER(SEARCH("Director",A43)),ISNUMBER(SEARCH("Head",A43)),ISNUMBER(SEARCH("VP",A43))),"Management","Mid-Level"))) -> Mid-Level | C43: =IF(ISNUMBER(SEARCH("Machine Learn",A43)),"ML Engineer",IF(ISNUMBER(SEARCH("Data Engineer",A43)),"Data Engineer",IF(ISNUMBER(SEARCH("Data Analyst",A43)),"Data Analyst",IF(ISNUMBER(SEARCH("Business Analyst",A43)),"Business Analyst",IF(ISNUMBER(SEARCH("Research",A43)),"Research Scientist",IF(ISNUMBER(SEARCH("Manager",A43)),"DS Manager",IF(ISNUMBER(SEARCH("Director",A43)),"Director/VP","Data Scientist"))))))) -> Data Engineer | D43: 3.6 | E43: Marlborough, MA | F43: =IFERROR(LEFT(E43, FIND(",", E43)-1), E43) -> Marlborough | G43: 18264 | H43: -1 | I43: 68 | J43: 129 | K43: 98.5 | L43: =IF(K43<50,"<$50K",IF(K43<75,"$50–75K",IF(K43<100,"$75–100K",IF(K43<125,"$100–125K",IF(K43<150,"$125–150K",">$150K"))))) -> $75–100K | M43: -1
A44: Data Scientist - Algorithms & Inference | B44: =IF(OR(ISNUMBER(SEARCH("Senior",A44)),ISNUMBER(SEARCH("Sr",A44)),ISNUMBER(SEARCH("Lead",A44)),ISNUMBER(SEARCH("Principal",A44))),"Senior",IF(OR(ISNUMBER(SEARCH("Junior",A44)),ISNUMBER(SEARCH("Jr",A44)),ISNUMBER(SEARCH("Entry",A44)),ISNUMBER(SEARCH("Associate",A44))),"Junior",IF(OR(ISNUMBER(SEARCH("Manager",A44)),ISNUMBER(SEARCH("Director",A44)),ISNUMBER(SEARCH("Head",A44)),ISNUMBER(SEARCH("VP",A44))),"Management","Mid-Level"))) -> Mid-Level | C44: =IF(ISNUMBER(SEARCH("Machine Learn",A44)),"ML Engineer",IF(ISNUMBER(SEARCH("Data Engineer",A44)),"Data Engineer",IF(ISNUMBER(SEARCH("Data Analyst",A44)),"Data Analyst",IF(ISNUMBER(SEARCH("Business Analyst",A44)),"Business Analyst",IF(ISNUMBER(SEARCH("Research",A44)),"Research Scientist",IF(ISNUMBER(SEARCH("Manager",A44)),"DS Manager",IF(ISNUMBER(SEARCH("Director",A44)),"Director/VP","Data Scientist"))))))) -> Data Scientist | D44: 4.2 | E44: San Francisco, CA | F44: =IFERROR(LEFT(E44, FIND(",", E44)-1), E44) -> San Francisco | G44: 51 - 200 | H44: Enterprise Software & Network Solutions | I44: 110 | J44: 175 | K44: 142.5 | L44: =IF(K44<50,"<$50K",IF(K44<75,"$50–75K",IF(K44<100,"$75–100K",IF(K44<125,"$100–125K",IF(K44<150,"$125–150K",">$150K"))))) -> $125–150K | M44: 11
A45: Scientist | B45: =IF(OR(ISNUMBER(SEARCH("Senior",A45)),ISNUMBER(SEARCH("Sr",A45)),ISNUMBER(SEARCH("Lead",A45)),ISNUMBER(SEARCH("Principal",A45))),"Senior",IF(OR(ISNUMBER(SEARCH("Junior",A45)),ISNUMBER(SEARCH("Jr",A45)),ISNUMBER(SEARCH("Entry",A45)),ISNUMBER(SEARCH("Associate",A45))),"Junior",IF(OR(ISNUMBER(SEARCH("Manager",A45)),ISNUMBER(SEARCH("Director",A45)),ISNUMBER(SEARCH("Head",A45)),ISNUMBER(SEARCH("VP",A45))),"Management","Mid-Level"))) -> Mid-Level | C45: =IF(ISNUMBER(SEARCH("Machine Learn",A45)),"ML Engineer",IF(ISNUMBER(SEARCH("Data Engineer",A45)),"Data Engineer",IF(ISNUMBER(SEARCH("Data Analyst",A45)),"Data Analyst",IF(ISNUMBER(SEARCH("Business Analyst",A45)),"Business Analyst",IF(ISNUMBER(SEARCH("Research",A45)),"Research Scientist",IF(ISNUMBER(SEARCH("Manager",A45)),"DS Manager",IF(ISNUMBER(SEARCH("Director",A45)),"Director/VP","Data Scientist"))))))) -> Data Scientist | D45: 3.4 | E45: Allendale, NJ | F45: =IFERROR(LEFT(E45, FIND(",", E45)-1), E45) -> Allendale | G45: 5001 - 10000 | H45: Consumer Products Manufacturing | I45: 52 | J45: 113 | K45: 82.5 | L45: =IF(K45<50,"<$50K",IF(K45<75,"$50–75K",IF(K45<100,"$75–100K",IF(K45<125,"$100–125K",IF(K45<150,"$125–150K",">$150K"))))) -> $75–100K | M45: 6
A46: Senior Data Scientist | B46: =IF(OR(ISNUMBER(SEARCH("Senior",A46)),ISNUMBER(SEARCH("Sr",A46)),ISNUMBER(SEARCH("Lead",A46)),ISNUMBER(SEARCH("Principal",A46))),"Senior",IF(OR(ISNUMBER(SEARCH("Junior",A46)),ISNUMBER(SEARCH("Jr",A46)),ISNUMBER(SEARCH("Entry",A46)),ISNUMBER(SEARCH("Associate",A46))),"Junior",IF(OR(ISNUMBER(SEARCH("Manager",A46)),ISNUMBER(SEARCH("Director",A46)),ISNUMBER(SEARCH("Head",A46)),ISNUMBER(SEARCH("VP",A46))),"Management","Mid-Level"))) -> Senior | C46: =IF(ISNUMBER(SEARCH("Machine Learn",A46)),"ML Engineer",IF(ISNUMBER(SEARCH("Data Engineer",A46)),"Data Engineer",IF(ISNUMBER(SEARCH("Data Analyst",A46)),"Data Analyst",IF(ISNUMBER(SEARCH("Business Analyst",A46)),"Business Analyst",IF(ISNUMBER(SEARCH("Research",A46)),"Research Scientist",IF(ISNUMBER(SEARCH("Manager",A46)),"DS Manager",IF(ISNUMBER(SEARCH("Director",A46)),"Director/VP","Data Scientist"))))))) -> Data Scientist | D46: 4.3 | E46: Chicago, IL | F46: =IFERROR(LEFT(E46, FIND(",", E46)-1), E46) -> Chicago | G46: 1001 - 5000 | H46: Real Estate | I46: 110 | J46: 150 | K46: 130 | L46: =IF(K46<50,"<$50K",IF(K46<75,"$50–75K",IF(K46<100,"$75–100K",IF(K46<125,"$100–125K",IF(K46<150,"$125–150K",">$150K"))))) -> $125–150K | M46: 28
A47: Data Scientist | B47: =IF(OR(ISNUMBER(SEARCH("Senior",A47)),ISNUMBER(SEARCH("Sr",A47)),ISNUMBER(SEARCH("Lead",A47)),ISNUMBER(SEARCH("Principal",A47))),"Senior",IF(OR(ISNUMBER(SEARCH("Junior",A47)),ISNUMBER(SEARCH("Jr",A47)),ISNUMBER(SEARCH("Entry",A47)),ISNUMBER(SEARCH("Associate",A47))),"Junior",IF(OR(ISNUMBER(SEARCH("Manager",A47)),ISNUMBER(SEARCH("Director",A47)),ISNUMBER(SEARCH("Head",A47)),ISNUMBER(SEARCH("VP",A47))),"Management","Mid-Level"))) -> Mid-Level | C47: =IF(ISNUMBER(SEARCH("Machine Learn",A47)),"ML Engineer",IF(ISNUMBER(SEARCH("Data Engineer",A47)),"Data Engineer",IF(ISNUMBER(SEARCH("Data Analyst",A47)),"Data Analyst",IF(ISNUMBER(SEARCH("Business Analyst",A47)),"Business Analyst",IF(ISNUMBER(SEARCH("Research",A47)),"Research Scientist",IF(ISNUMBER(SEARCH("Manager",A47)),"DS Manager",IF(ISNUMBER(SEARCH("Director",A47)),"Director/VP","Data Scientist"))))))) -> Data Scientist | D47: 5 | E47: Washington, DC | F47: =IFERROR(LEFT(E47, FIND(",", E47)-1), E47) -> Washington | G47: unknown | H47: Enterprise Software & Network Solutions | I47: 150 | J47: 160 | K47: 155 | L47: =IF(K47<50,"<$50K",IF(K47<75,"$50–75K",IF(K47<100,"$75–100K",IF(K47<125,"$100–125K",IF(K47<150,"$125–150K",">$150K"))))) -> >$150K | M47: -1
A48: Lead Data Scientist | B48: =IF(OR(ISNUMBER(SEARCH("Senior",A48)),ISNUMBER(SEARCH("Sr",A48)),ISNUMBER(SEARCH("Lead",A48)),ISNUMBER(SEARCH("Principal",A48))),"Senior",IF(OR(ISNUMBER(SEARCH("Junior",A48)),ISNUMBER(SEARCH("Jr",A48)),ISNUMBER(SEARCH("Entry",A48)),ISNUMBER(SEARCH("Associate",A48))),"Junior",IF(OR(ISNUMBER(SEARCH("Manager",A48)),ISNUMBER(SEARCH("Director",A48)),ISNUMBER(SEARCH("Head",A48)),ISNUMBER(SEARCH("VP",A48))),"Management","Mid-Level"))) -> Senior | C48: =IF(ISNUMBER(SEARCH("Machine Learn",A48)),"ML Engineer",IF(ISNUMBER(SEARCH("Data Engineer",A48)),"Data Engineer",IF(ISNUMBER(SEARCH("Data Analyst",A48)),"Data Analyst",IF(ISNUMBER(SEARCH("Business Analyst",A48)),"Business Analyst",IF(ISNUMBER(SEARCH("Research",A48)),"Research Scientist",IF(ISNUMBER(SEARCH("Manager",A48)),"DS Manager",IF(ISNUMBER(SEARCH("Director",A48)),"Director/VP","Data Scientist"))))))) -> Data Scientist | D48: 3.7 | E48: Bellevue, WA | F48: =IFERROR(LEFT(E48, FIND(",", E48)-1), E48) -> Bellevue | G48: 10000+ | H48: IT Services | I48: 158 | J48: 211 | K48: 184.5 | L48: =IF(K48<50,"<$50K",IF(K48<75,"$50–75K",IF(K48<100,"$75–100K",IF(K48<125,"$100–125K",IF(K48<150,"$125–150K",">$150K"))))) -> >$150K | M48: 63
A49: Associate Data Analyst | B49: =IF(OR(ISNUMBER(SEARCH("Senior",A49)),ISNUMBER(SEARCH("Sr",A49)),ISNUMBER(SEARCH("Lead",A49)),ISNUMBER(SEARCH("Principal",A49))),"Senior",IF(OR(ISNUMBER(SEARCH("Junior",A49)),ISNUMBER(SEARCH("Jr",A49)),ISNUMBER(SEARCH("Entry",A49)),ISNUMBER(SEARCH("Associate",A49))),"Junior",IF(OR(ISNUMBER(SEARCH("Manager",A49)),ISNUMBER(SEARCH("Director",A49)),ISNUMBER(SEARCH("Head",A49)),ISNUMBER(SEARCH("VP",A49))),"Management","Mid-Level"))) -> Junior | C49: =IF(ISNUMBER(SEARCH("Machine Learn",A49)),"ML Engineer",IF(ISNUMBER(SEARCH("Data Engineer",A49)),"Data Engineer",IF(ISNUMBER(SEARCH("Data Analyst",A49)),"Data Analyst",IF(ISNUMBER(SEARCH("Business Analyst",A49)),"Business Analyst",IF(ISNUMBER(SEARCH("Research",A49)),"Research Scientist",IF(ISNUMBER(SEARCH("Manager",A49)),"DS Manager",IF(ISNUMBER(SEARCH("Director",A49)),"Director/VP","Data Scientist"))))))) -> Data Analyst | D49: 3.1 | E49: Longmont, CO | F49: =IFERROR(LEFT(E49, FIND(",", E49)-1), E49) -> Longmont | G49: 5001 - 10000 | H49: Enterprise Software & Network Solutions | I49: 20 | J49: 39 | K49: 29.5 | L49: =IF(K49<50,"<$50K",IF(K49<75,"$50–75K",IF(K49<100,"$75–100K",IF(K49<125,"$100–125K",IF(K49<150,"$125–150K",">$150K"))))) -> <$50K | M49: 35
A50: Spectral Scientist/Engineer | B50: =IF(OR(ISNUMBER(SEARCH("Senior",A50)),ISNUMBER(SEARCH("Sr",A50)),ISNUMBER(SEARCH("Lead",A50)),ISNUMBER(SEARCH("Principal",A50))),"Senior",IF(OR(ISNUMBER(SEARCH("Junior",A50)),ISNUMBER(SEARCH("Jr",A50)),ISNUMBER(SEARCH("Entry",A50)),ISNUMBER(SEARCH("Associate",A50))),"Junior",IF(OR(ISNUMBER(SEARCH("Manager",A50)),ISNUMBER(SEARCH("Director",A50)),ISNUMBER(SEARCH("Head",A50)),ISNUMBER(SEARCH("VP",A50))),"Management","Mid-Level"))) -> Mid-Level | C50: =IF(ISNUMBER(SEARCH("Machine Learn",A50)),"ML Engineer",IF(ISNUMBER(SEARCH("Data Engineer",A50)),"Data Engineer",IF(ISNUMBER(SEARCH("Data Analyst",A50)),"Data Analyst",IF(ISNUMBER(SEARCH("Business Analyst",A50)),"Business Analyst",IF(ISNUMBER(SEARCH("Research",A50)),"Research Scientist",IF(ISNUMBER(SEARCH("Manager",A50)),"DS Manager",IF(ISNUMBER(SEARCH("Director",A50)),"Director/VP","Data Scientist"))))))) -> Data Scientist | D50: 4.7 | E50: Beavercreek, OH | F50: =IFERROR(LEFT(E50, FIND(",", E50)-1), E50) -> Beavercreek | G50: 501 - 1000 | H50: Aerospace & Defense | I50: 56 | J50: 117 | K50: 86.5 | L50: =IF(K50<50,"<$50K",IF(K50<75,"$50–75K",IF(K50<100,"$75–100K",IF(K50<125,"$100–125K",IF(K50<150,"$125–150K",">$150K"))))) -> $75–100K | M50: 22
A51: College Hire - Data Scientist - Open to December 2019 Graduates | B51: =IF(OR(ISNUMBER(SEARCH("Senior",A51)),ISNUMBER(SEARCH("Sr",A51)),ISNUMBER(SEARCH("Lead",A51)),ISNUMBER(SEARCH("Principal",A51))),"Senior",IF(OR(ISNUMBER(SEARCH("Junior",A51)),ISNUMBER(SEARCH("Jr",A51)),ISNUMBER(SEARCH("Entry",A51)),ISNUMBER(SEARCH("Associate",A51))),"Junior",IF(OR(ISNUMBER(SEARCH("Manager",A51)),ISNUMBER(SEARCH("Director",A51)),ISNUMBER(SEARCH("Head",A51)),ISNUMBER(SEARCH("VP",A51))),"Management","Mid-Level"))) -> Mid-Level | C51: =IF(ISNUMBER(SEARCH("Machine Learn",A51)),"ML Engineer",IF(ISNUMBER(SEARCH("Data Engineer",A51)),"Data Engineer",IF(ISNUMBER(SEARCH("Data Analyst",A51)),"Data Analyst",IF(ISNUMBER(SEARCH("Business Analyst",A51)),"Business Analyst",IF(ISNUMBER(SEARCH("Research",A51)),"Research Scientist",IF(ISNUMBER(SEARCH("Manager",A51)),"DS Manager",IF(ISNUMBER(SEARCH("Director",A51)),"Director/VP","Data Scientist"))))))) -> Data Scientist | D51: 3.7 | E51: Peoria, IL | F51: =IFERROR(LEFT(E51, FIND(",", E51)-1), E51) -> Peoria | G51: 10000+ | H51: Industrial Manufacturing | I51: 63 | J51: 99 | K51: 81 | L51: =IF(K51<50,"<$50K",IF(K51<75,"$50–75K",IF(K51<100,"$75–100K",IF(K51<125,"$100–125K",IF(K51<150,"$125–150K",">$150K"))))) -> $75–100K | M51: 96
A52: Data Scientist | B52: =IF(OR(ISNUMBER(SEARCH("Senior",A52)),ISNUMBER(SEARCH("Sr",A52)),ISNUMBER(SEARCH("Lead",A52)),ISNUMBER(SEARCH("Principal",A52))),"Senior",IF(OR(ISNUMBER(SEARCH("Junior",A52)),ISNUMBER(SEARCH("Jr",A52)),ISNUMBER(SEARCH("Entry",A52)),ISNUMBER(SEARCH("Associate",A52))),"Junior",IF(OR(ISNUMBER(SEARCH("Manager",A52)),ISNUMBER(SEARCH("Director",A52)),ISNUMBER(SEARCH("Head",A52)),ISNUMBER(SEARCH("VP",A52))),"Management","Mid-Level"))) -> Mid-Level | C52: =IF(ISNUMBER(SEARCH("Machine Learn",A52)),"ML Engineer",IF(ISNUMBER(SEARCH("Data Engineer",A52)),"Data Engineer",IF(ISNUMBER(SEARCH("Data Analyst",A52)),"Data Analyst",IF(ISNUMBER(SEARCH("Business Analyst",A52)),"Business Analyst",IF(ISNUMBER(SEARCH("Research",A52)),"Research Scientist",IF(ISNUMBER(SEARCH("Manager",A52)),"DS Manager",IF(ISNUMBER(SEARCH("Director",A52)),"Director/VP","Data Scientist"))))))) -> Data Scientist | D52: 3.8 | E52: Fort Lauderdale, FL | F52: =IFERROR(LEFT(E52, FIND(",", E52)-1), E52) -> Fort Lauderdale | G52: 501 - 1000 | H52: Advertising & Marketing | I52: 68 | J52: 114 | K52: 91 | L52: =IF(K52<50,"<$50K",IF(K52<75,"$50–75K",IF(K52<100,"$75–100K",IF(K52<125,"$100–125K",IF(K52<150,"$125–150K",">$150K"))))) -> $75–100K | M52: 37
A53: Data Scientist, Office of Data Science | B53: =IF(OR(ISNUMBER(SEARCH("Senior",A53)),ISNUMBER(SEARCH("Sr",A53)),ISNUMBER(SEARCH("Lead",A53)),ISNUMBER(SEARCH("Principal",A53))),"Senior",IF(OR(ISNUMBER(SEARCH("Junior",A53)),ISNUMBER(SEARCH("Jr",A53)),ISNUMBER(SEARCH("Entry",A53)),ISNUMBER(SEARCH("Associate",A53))),"Junior",IF(OR(ISNUMBER(SEARCH("Manager",A53)),ISNUMBER(SEARCH("Director",A53)),ISNUMBER(SEARCH("Head",A53)),ISNUMBER(SEARCH("VP",A53))),"Management","Mid-Level"))) -> Mid-Level | C53: =IF(ISNUMBER(SEARCH("Machine Learn",A53)),"ML Engineer",IF(ISNUMBER(SEARCH("Data Engineer",A53)),"Data Engineer",IF(ISNUMBER(SEARCH("Data Analyst",A53)),"Data Analyst",IF(ISNUMBER(SEARCH("Business Analyst",A53)),"Business Analyst",IF(ISNUMBER(SEARCH("Research",A53)),"Research Scientist",IF(ISNUMBER(SEARCH("Manager",A53)),"DS Manager",IF(ISNUMBER(SEARCH("Director",A53)),"Director/VP","Data Scientist"))))))) -> Data Scientist | D53: 3.3 | E53: Boston, MA | F53: =IFERROR(LEFT(E53, FIND(",", E53)-1), E53) -> Boston | G53: 10000+ | H53: Insurance Carriers | I53: 86 | J53: 143 | K53: 114.5 | L53: =IF(K53<50,"<$50K",IF(K53<75,"$50–75K",IF(K53<100,"$75–100K",IF(K53<125,"$100–125K",IF(K53<150,"$125–150K",">$150K"))))) -> $100–125K | M53: 109
A54: Data Science Analyst | B54: =IF(OR(ISNUMBER(SEARCH("Senior",A54)),ISNUMBER(SEARCH("Sr",A54)),ISNUMBER(SEARCH("Lead",A54)),ISNUMBER(SEARCH("Principal",A54))),"Senior",IF(OR(ISNUMBER(SEARCH("Junior",A54)),ISNUMBER(SEARCH("Jr",A54)),ISNUMBER(SEARCH("Entry",A54)),ISNUMBER(SEARCH("Associate",A54))),"Junior",IF(OR(ISNUMBER(SEARCH("Manager",A54)),ISNUMBER(SEARCH("Director",A54)),ISNUMBER(SEARCH("Head",A54)),ISNUMBER(SEARCH("VP",A54))),"Management","Mid-Level"))) -> Mid-Level | C54: =IF(ISNUMBER(SEARCH("Machine Learn",A54)),"ML Engineer",IF(ISNUMBER(SEARCH("Data Engineer",A54)),"Data Engineer",IF(ISNUMBER(SEARCH("Data Analyst",A54)),"Data Analyst",IF(ISNUMBER(SEARCH("Business Analyst",A54)),"Business Analyst",IF(ISNUMBER(SEARCH("Research",A54)),"Research Scientist",IF(ISNUMBER(SEARCH("Manager",A54)),"DS Manager",IF(ISNUMBER(SEARCH("Director",A54)),"Director/VP","Data Scientist"))))))) -> Data Scientist | D54: 4.6 | E54: Huntsville, AL | F54: =IFERROR(LEFT(E54, FIND(",", E54)-1), E54) -> Huntsville | G54: 1001 - 5000 | H54: Aerospace & Defense | I54: 41 | J54: 95 | K54: 68 | L54: =IF(K54<50,"<$50K",IF(K54<75,"$50–75K",IF(K54<100,"$75–100K",IF(K54<125,"$100–125K",IF(K54<150,"$125–150K",">$150K"))))) -> $50–75K | M54: 19
A55: Data Scientist | B55: =IF(OR(ISNUMBER(SEARCH("Senior",A55)),ISNUMBER(SEARCH("Sr",A55)),ISNUMBER(SEARCH("Lead",A55)),ISNUMBER(SEARCH("Principal",A55))),"Senior",IF(OR(ISNUMBER(SEARCH("Junior",A55)),ISNUMBER(SEARCH("Jr",A55)),ISNUMBER(SEARCH("Entry",A55)),ISNUMBER(SEARCH("Associate",A55))),"Junior",IF(OR(ISNUMBER(SEARCH("Manager",A55)),ISNUMBER(SEARCH("Director",A55)),ISNUMBER(SEARCH("Head",A55)),ISNUMBER(SEARCH("VP",A55))),"Management","Mid-Level"))) -> Mid-Level | C55: =IF(ISNUMBER(SEARCH("Machine Learn",A55)),"ML Engineer",IF(ISNUMBER(SEARCH("Data Engineer",A55)),"Data Engineer",IF(ISNUMBER(SEARCH("Data Analyst",A55)),"Data Analyst",IF(ISNUMBER(SEARCH("Business Analyst",A55)),"Business Analyst",IF(ISNUMBER(SEARCH("Research",A55)),"Research Scientist",IF(ISNUMBER(SEARCH("Manager",A55)),"DS Manager",IF(ISNUMBER(SEARCH("Director",A55)),"Director/VP","Data Scientist"))))))) -> Data Scientist | D55: 3.7 | E55: Armonk, NY | F55: =IFERROR(LEFT(E55, FIND(",", E55)-1), E55) -> Armonk | G55: 10000+ | H55: Insurance Agencies & Brokerages | I55: 86 | J55: 144 | K55: 115 | L55: =IF(K55<50,"<$50K",IF(K55<75,"$50–75K",IF(K55<100,"$75–100K",IF(K55<125,"$100–125K",IF(K55<150,"$125–150K",">$150K"))))) -> $100–125K | M55: 158
... A69: Data Scientist - Research | B69: =IF(OR(ISNUMBER(SEARCH("Senior",A69)),ISNUMBER(SEARCH("Sr",A69)),ISNUMBER(SEARCH("Lead",A69)),ISNUMBER(SEARCH("Principal",A69))),"Senior",IF(OR(ISNUMBER(SEARCH("Junior",A69)),ISNUMBER(SEARCH("Jr",A69)),ISNUMBER(SEARCH("Entry",A69)),ISNUMBER(SEARCH("Associate",A69))),"Junior",IF(OR(ISNUMBER(SEARCH("Manager",A69)),ISNUMBER(SEARCH("Director",A69)),ISNUMBER(SEARCH("Head",A69)),ISNUMBER(SEARCH("VP",A69))),"Management","Mid-Level"))) -> Mid-Level | C69: =IF(ISNUMBER(SEARCH("Machine Learn",A69)),"ML Engineer",IF(ISNUMBER(SEARCH("Data Engineer",A69)),"Data Engineer",IF(ISNUMBER(SEARCH("Data Analyst",A69)),"Data Analyst",IF(ISNUMBER(SEARCH("Business Analyst",A69)),"Business Analyst",IF(ISNUMBER(SEARCH("Research",A69)),"Research Scientist",IF(ISNUMBER(SEARCH("Manager",A69)),"DS Manager",IF(ISNUMBER(SEARCH("Director",A69)),"Director/VP","Data Scientist"))))))) -> Research Scientist | D69: 3.1 | E69: Boston, MA | F69: =IFERROR(LEFT(E69, FIND(",", E69)-1), E69) -> Boston | G69: 201 - 500 | H69: Advertising & Marketing | I69: 41 | J69: 72 | K69: 56.5 | L69: =IF(K69<50,"<$50K",IF(K69<75,"$50–75K",IF(K69<100,"$75–100K",IF(K69<125,"$100–125K",IF(K69<150,"$125–150K",">$150K"))))) -> $50–75K | M69: 22
A70: Data Scientist | B70: =IF(OR(ISNUMBER(SEARCH("Senior",A70)),ISNUMBER(SEARCH("Sr",A70)),ISNUMBER(SEARCH("Lead",A70)),ISNUMBER(SEARCH("Principal",A70))),"Senior",IF(OR(ISNUMBER(SEARCH("Junior",A70)),ISNUMBER(SEARCH("Jr",A70)),ISNUMBER(SEARCH("Entry",A70)),ISNUMBER(SEARCH("Associate",A70))),"Junior",IF(OR(ISNUMBER(SEARCH("Manager",A70)),ISNUMBER(SEARCH("Director",A70)),ISNUMBER(SEARCH("Head",A70)),ISNUMBER(SEARCH("VP",A70))),"Management","Mid-Level"))) -> Mid-Level | C70: =IF(ISNUMBER(SEARCH("Machine Learn",A70)),"ML Engineer",IF(ISNUMBER(SEARCH("Data Engineer",A70)),"Data Engineer",IF(ISNUMBER(SEARCH("Data Analyst",A70)),"Data Analyst",IF(ISNUMBER(SEARCH("Business Analyst",A70)),"Business Analyst",IF(ISNUMBER(SEARCH("Research",A70)),"Research Scientist",IF(ISNUMBER(SEARCH("Manager",A70)),"DS Manager",IF(ISNUMBER(SEARCH("Director",A70)),"Director/VP","Data Scientist"))))))) -> Data Scientist | D70: 3.2 | E70: Philadelphia, PA | F70: =IFERROR(LEFT(E70, FIND(",", E70)-1), E70) -> Philadelphia | G70: 18264 | H70: Staffing & Outsourcing | I70: 96 | J70: 161 | K70: 128.5 | L70: =IF(K70<50,"<$50K",IF(K70<75,"$50–75K",IF(K70<100,"$75–100K",IF(K70<125,"$100–125K",IF(K70<150,"$125–150K",">$150K"))))) -> $125–150K | M70: -1
A71: R&D Data Analysis Scientist | B71: =IF(OR(ISNUMBER(SEARCH("Senior",A71)),ISNUMBER(SEARCH("Sr",A71)),ISNUMBER(SEARCH("Lead",A71)),ISNUMBER(SEARCH("Principal",A71))),"Senior",IF(OR(ISNUMBER(SEARCH("Junior",A71)),ISNUMBER(SEARCH("Jr",A71)),ISNUMBER(SEARCH("Entry",A71)),ISNUMBER(SEARCH("Associate",A71))),"Junior",IF(OR(ISNUMBER(SEARCH("Manager",A71)),ISNUMBER(SEARCH("Director",A71)),ISNUMBER(SEARCH("Head",A71)),ISNUMBER(SEARCH("VP",A71))),"Management","Mid-Level"))) -> Mid-Level | C71: =IF(ISNUMBER(SEARCH("Machine Learn",A71)),"ML Engineer",IF(ISNUMBER(SEARCH("Data Engineer",A71)),"Data Engineer",IF(ISNUMBER(SEARCH("Data Analyst",A71)),"Data Analyst",IF(ISNUMBER(SEARCH("Business Analyst",A71)),"Business Analyst",IF(ISNUMBER(SEARCH("Research",A71)),"Research Scientist",IF(ISNUMBER(SEARCH("Manager",A71)),"DS Manager",IF(ISNUMBER(SEARCH("Director",A71)),"Director/VP","Data Scientist"))))))) -> Data Scientist | D71: 4 | E71: Vancouver, WA | F71: =IFERROR(LEFT(E71, FIND(",", E71)-1), E71) -> Vancouver | G71: 10000+ | H71: Computer Hardware & Software | I71: 65 | J71: 130 | K71: 97.5 | L71: =IF(K71<50,"<$50K",IF(K71<75,"$50–75K",IF(K71<100,"$75–100K",IF(K71<125,"$100–125K",IF(K71<150,"$125–150K",">$150K"))))) -> $75–100K | M71: 82
A72: Analytics Consultant | B72: =IF(OR(ISNUMBER(SEARCH("Senior",A72)),ISNUMBER(SEARCH("Sr",A72)),ISNUMBER(SEARCH("Lead",A72)),ISNUMBER(SEARCH("Principal",A72))),"Senior",IF(OR(ISNUMBER(SEARCH("Junior",A72)),ISNUMBER(SEARCH("Jr",A72)),ISNUMBER(SEARCH("Entry",A72)),ISNUMBER(SEARCH("Associate",A72))),"Junior",IF(OR(ISNUMBER(SEARCH("Manager",A72)),ISNUMBER(SEARCH("Director",A72)),ISNUMBER(SEARCH("Head",A72)),ISNUMBER(SEARCH("VP",A72))),"Management","Mid-Level"))) -> Mid-Level | C72: =IF(ISNUMBER(SEARCH("Machine Learn",A72)),"ML Engineer",IF(ISNUMBER(SEARCH("Data Engineer",A72)),"Data Engineer",IF(ISNUMBER(SEARCH("Data Analyst",A72)),"Data Analyst",IF(ISNUMBER(SEARCH("Business Analyst",A72)),"Business Analyst",IF(ISNUMBER(SEARCH("Research",A72)),"Research Scientist",IF(ISNUMBER(SEARCH("Manager",A72)),"DS Manager",IF(ISNUMBER(SEARCH("Director",A72)),"Director/VP","Data Scientist"))))))) -> Data Scientist | D72: 4.4 | E72: Indianapolis, IN | F72: =IFERROR(LEFT(E72, FIND(",", E72)-1), E72) -> Indianapolis | G72: 18264 | H72: Enterprise Software & Network Solutions | I72: 52 | J72: 81 | K72: 66.5 | L72: =IF(K72<50,"<$50K",IF(K72<75,"$50–75K",IF(K72<100,"$75–100K",IF(K72<125,"$100–125K",IF(K72<150,"$125–150K",">$150K"))))) -> $50–75K | M72: 6
A73: Director, Data Science | B73: =IF(OR(ISNUMBER(SEARCH("Senior",A73)),ISNUMBER(SEARCH("Sr",A73)),ISNUMBER(SEARCH("Lead",A73)),ISNUMBER(SEARCH("Principal",A73))),"Senior",IF(OR(ISNUMBER(SEARCH("Junior",A73)),ISNUMBER(SEARCH("Jr",A73)),ISNUMBER(SEARCH("Entry",A73)),ISNUMBER(SEARCH("Associate",A73))),"Junior",IF(OR(ISNUMBER(SEARCH("Manager",A73)),ISNUMBER(SEARCH("Director",A73)),ISNUMBER(SEARCH("Head",A73)),ISNUMBER(SEARCH("VP",A73))),"Management","Mid-Level"))) -> Management | C73: =IF(ISNUMBER(SEARCH("Machine Learn",A73)),"ML Engineer",IF(ISNUMBER(SEARCH("Data Engineer",A73)),"Data Engineer",IF(ISNUMBER(SEARCH("Data Analyst",A73)),"Data Analyst",IF(ISNUMBER(SEARCH("Business Analyst",A73)),"Business Analyst",IF(ISNUMBER(SEARCH("Research",A73)),"Research Scientist",IF(ISNUMBER(SEARCH("Manager",A73)),"DS Manager",IF(ISNUMBER(SEARCH("Director",A73)),"Director/VP","Data Scientist"))))))) -> Director/VP | D73: 3.6 | E73: Lake Forest, IL | F73: =IFERROR(LEFT(E73, FIND(",", E73)-1), E73) -> Lake Forest | G73: 10000+ | H73: Wholesale | I73: 139 | J73: 220 | K73: 179.5 | L73: =IF(K73<50,"<$50K",IF(K73<75,"$50–75K",IF(K73<100,"$75–100K",IF(K73<125,"$100–125K",IF(K73<150,"$125–150K",">$150K"))))) -> >$150K | M73: 94
A74: Scientist | B74: =IF(OR(ISNUMBER(SEARCH("Senior",A74)),ISNUMBER(SEARCH("Sr",A74)),ISNUMBER(SEARCH("Lead",A74)),ISNUMBER(SEARCH("Principal",A74))),"Senior",IF(OR(ISNUMBER(SEARCH("Junior",A74)),ISNUMBER(SEARCH("Jr",A74)),ISNUMBER(SEARCH("Entry",A74)),ISNUMBER(SEARCH("Associate",A74))),"Junior",IF(OR(ISNUMBER(SEARCH("Manager",A74)),ISNUMBER(SEARCH("Director",A74)),ISNUMBER(SEARCH("Head",A74)),ISNUMBER(SEARCH("VP",A74))),"Management","Mid-Level"))) -> Mid-Level | C74: =IF(ISNUMBER(SEARCH("Machine Learn",A74)),"ML Engineer",IF(ISNUMBER(SEARCH("Data Engineer",A74)),"Data Engineer",IF(ISNUMBER(SEARCH("Data Analyst",A74)),"Data Analyst",IF(ISNUMBER(SEARCH("Business Analyst",A74)),"Business Analyst",IF(ISNUMBER(SEARCH("Research",A74)),"Research Scientist",IF(ISNUMBER(SEARCH("Manager",A74)),"DS Manager",IF(ISNUMBER(SEARCH("Director",A74)),"Director/VP","Data Scientist"))))))) -> Data Scientist | D74: 2.7 | E74: Maryland Heights, MO | F74: =IFERROR(LEFT(E74, FIND(",", E74)-1), E74) -> Maryland Heights | G74: 501 - 1000 | H74: Research & Development | I74: 50 | J74: 102 | K74: 76 | L74: =IF(K74<50,"<$50K",IF(K74<75,"$50–75K",IF(K74<100,"$75–100K",IF(K74<125,"$100–125K",IF(K74<150,"$125–150K",">$150K"))))) -> $75–100K | M74: 43
A75: Data Scientist SR | B75: =IF(OR(ISNUMBER(SEARCH("Senior",A75)),ISNUMBER(SEARCH("Sr",A75)),ISNUMBER(SEARCH("Lead",A75)),ISNUMBER(SEARCH("Principal",A75))),"Senior",IF(OR(ISNUMBER(SEARCH("Junior",A75)),ISNUMBER(SEARCH("Jr",A75)),ISNUMBER(SEARCH("Entry",A75)),ISNUMBER(SEARCH("Associate",A75))),"Junior",IF(OR(ISNUMBER(SEARCH("Manager",A75)),ISNUMBER(SEARCH("Director",A75)),ISNUMBER(SEARCH("Head",A75)),ISNUMBER(SEARCH("VP",A75))),"Management","Mid-Level"))) -> Senior | C75: =IF(ISNUMBER(SEARCH("Machine Learn",A75)),"ML Engineer",IF(ISNUMBER(SEARCH("Data Engineer",A75)),"Data Engineer",IF(ISNUMBER(SEARCH("Data Analyst",A75)),"Data Analyst",IF(ISNUMBER(SEARCH("Business Analyst",A75)),"Business Analyst",IF(ISNUMBER(SEARCH("Research",A75)),"Research Scientist",IF(ISNUMBER(SEARCH("Manager",A75)),"DS Manager",IF(ISNUMBER(SEARCH("Director",A75)),"Director/VP","Data Scientist"))))))) -> Data Scientist | D75: 3.9 | E75: Charlottesville, VA | F75: =IFERROR(LEFT(E75, FIND(",", E75)-1), E75) -> Charlottesville | G75: 501 - 1000 | H75: IT Services | I75: 85 | J75: 139 | K75: 112 | L75: =IF(K75<50,"<$50K",IF(K75<75,"$50–75K",IF(K75<100,"$75–100K",IF(K75<125,"$100–125K",IF(K75<150,"$125–150K",">$150K"))))) -> $100–125K | M75: 11
A76: Data Scientist | B76: =IF(OR(ISNUMBER(SEARCH("Senior",A76)),ISNUMBER(SEARCH("Sr",A76)),ISNUMBER(SEARCH("Lead",A76)),ISNUMBER(SEARCH("Principal",A76))),"Senior",IF(OR(ISNUMBER(SEARCH("Junior",A76)),ISNUMBER(SEARCH("Jr",A76)),ISNUMBER(SEARCH("Entry",A76)),ISNUMBER(SEARCH("Associate",A76))),"Junior",IF(OR(ISNUMBER(SEARCH("Manager",A76)),ISNUMBER(SEARCH("Director",A76)),ISNUMBER(SEARCH("Head",A76)),ISNUMBER(SEARCH("VP",A76))),"Management","Mid-Level"))) -> Mid-Level | C76: =IF(ISNUMBER(SEARCH("Machine Learn",A76)),"ML Engineer",IF(ISNUMBER(SEARCH("Data Engineer",A76)),"Data Engineer",IF(ISNUMBER(SEARCH("Data Analyst",A76)),"Data Analyst",IF(ISNUMBER(SEARCH("Business Analyst",A76)),"Business Analyst",IF(ISNUMBER(SEARCH("Research",A76)),"Research Scientist",IF(ISNUMBER(SEARCH("Manager",A76)),"DS Manager",IF(ISNUMBER(SEARCH("Director",A76)),"Director/VP","Data Scientist"))))))) -> Data Scientist | D76: 3.1 | E76: Pittsburgh, PA | F76: =IFERROR(LEFT(E76, FIND(",", E76)-1), E76) -> Pittsburgh | G76: 1001 - 5000 | H76: Mining | I76: 74 | J76: 122 | K76: 98 | L76: =IF(K76<50,"<$50K",IF(K76<75,"$50–75K",IF(K76<100,"$75–100K",IF(K76<125,"$100–125K",IF(K76<150,"$125–150K",">$150K"))))) -> $75–100K | M76: 161
A77: R&D Sr Data Scientist | B77: =IF(OR(ISNUMBER(SEARCH("Senior",A77)),ISNUMBER(SEARCH("Sr",A77)),ISNUMBER(SEARCH("Lead",A77)),ISNUMBER(SEARCH("Principal",A77))),"Senior",IF(OR(ISNUMBER(SEARCH("Junior",A77)),ISNUMBER(SEARCH("Jr",A77)),ISNUMBER(SEARCH("Entry",A77)),ISNUMBER(SEARCH("Associate",A77))),"Junior",IF(OR(ISNUMBER(SEARCH("Manager",A77)),ISNUMBER(SEARCH("Director",A77)),ISNUMBER(SEARCH("Head",A77)),ISNUMBER(SEARCH("VP",A77))),"Management","Mid-Level"))) -> Senior | C77: =IF(ISNUMBER(SEARCH("Machine Learn",A77)),"ML Engineer",IF(ISNUMBER(SEARCH("Data Engineer",A77)),"Data Engineer",IF(ISNUMBER(SEARCH("Data Analyst",A77)),"Data Analyst",IF(ISNUMBER(SEARCH("Business Analyst",A77)),"Business Analyst",IF(ISNUMBER(SEARCH("Research",A77)),"Research Scientist",IF(ISNUMBER(SEARCH("Manager",A77)),"DS Manager",IF(ISNUMBER(SEARCH("Director",A77)),"Director/VP","Data Scientist"))))))) -> Data Scientist | D77: 4 | E77: Vancouver, WA | F77: =IFERROR(LEFT(E77, FIND(",", E77)-1), E77) -> Vancouver | G77: 10000+ | H77: Computer Hardware & Software | I77: 99 | J77: 157 | K77: 128 | L77: =IF(K77<50,"<$50K",IF(K77<75,"$50–75K",IF(K77<100,"$75–100K",IF(K77<125,"$100–125K",IF(K77<150,"$125–150K",">$150K"))))) -> $125–150K | M77: 82
A78: Customer Data Scientist/Sales Engineer (Bay | B78: =IF(OR(ISNUMBER(SEARCH("Senior",A78)),ISNUMBER(SEARCH("Sr",A78)),ISNUMBER(SEARCH("Lead",A78)),ISNUMBER(SEARCH("Principal",A78))),"Senior",IF(OR(ISNUMBER(SEARCH("Junior",A78)),ISNUMBER(SEARCH("Jr",A78)),ISNUMBER(SEARCH("Entry",A78)),ISNUMBER(SEARCH("Associate",A78))),"Junior",IF(OR(ISNUMBER(SEARCH("Manager",A78)),ISNUMBER(SEARCH("Director",A78)),ISNUMBER(SEARCH("Head",A78)),ISNUMBER(SEARCH("VP",A78))),"Management","Mid-Level"))) -> Mid-Level | C78: =IF(ISNUMBER(SEARCH("Machine Learn",A78)),"ML Engineer",IF(ISNUMBER(SEARCH("Data Engineer",A78)),"Data Engineer",IF(ISNUMBER(SEARCH("Data Analyst",A78)),"Data Analyst",IF(ISNUMBER(SEARCH("Business Analyst",A78)),"Business Analyst",IF(ISNUMBER(SEARCH("Research",A78)),"Research Scientist",IF(ISNUMBER(SEARCH("Manager",A78)),"DS Manager",IF(ISNUMBER(SEARCH("Director",A78)),"Director/VP","Data Scientist"))))))) -> Data Scientist | D78: 4.3 | E78: Mountain View, CA | F78: =IFERROR(LEFT(E78, FIND(",", E78)-1), E78) -> Mountain View | G78: 201 - 500 | H78: Enterprise Software & Network Solutions | I78: 79 | J78: 222 | K78: 150.5 | L78: =IF(K78<50,"<$50K",IF(K78<75,"$50–75K",IF(K78<100,"$75–100K",IF(K78<125,"$100–125K",IF(K78<150,"$125–150K",">$150K"))))) -> >$150K | M78: 10
A79: Research Scientist | B79: =IF(OR(ISNUMBER(SEARCH("Senior",A79)),ISNUMBER(SEARCH("Sr",A79)),ISNUMBER(SEARCH("Lead",A79)),ISNUMBER(SEARCH("Principal",A79))),"Senior",IF(OR(ISNUMBER(SEARCH("Junior",A79)),ISNUMBER(SEARCH("Jr",A79)),ISNUMBER(SEARCH("Entry",A79)),ISNUMBER(SEARCH("Associate",A79))),"Junior",IF(OR(ISNUMBER(SEARCH("Manager",A79)),ISNUMBER(SEARCH("Director",A79)),ISNUMBER(SEARCH("Head",A79)),ISNUMBER(SEARCH("VP",A79))),"Management","Mid-Level"))) -> Mid-Level | C79: =IF(ISNUMBER(SEARCH("Machine Learn",A79)),"ML Engineer",IF(ISNUMBER(SEARCH("Data Engineer",A79)),"Data Engineer",IF(ISNUMBER(SEARCH("Data Analyst",A79)),"Data Analyst",IF(ISNUMBER(SEARCH("Business Analyst",A79)),"Business Analyst",IF(ISNUMBER(SEARCH("Research",A79)),"Research Scientist",IF(ISNUMBER(SEARCH("Manager",A79)),"DS Manager",IF(ISNUMBER(SEARCH("Director",A79)),"Director/VP","Data Scientist"))))))) -> Research Scientist | D79: 1.9 | E79: Cambridge, MA | F79: =IFERROR(LEFT(E79, FIND(",", E79)-1), E79) -> Cambridge | G79: 51 - 200 | H79: Biotech & Pharmaceuticals | I79: 57 | J79: 118 | K79: 87.5 | L79: =IF(K79<50,"<$50K",IF(K79<75,"$50–75K",IF(K79<100,"$75–100K",IF(K79<125,"$100–125K",IF(K79<150,"$125–150K",">$150K"))))) -> $75–100K | M79: 21
A80: Data Scientist | B80: =IF(OR(ISNUMBER(SEARCH("Senior",A80)),ISNUMBER(SEARCH("Sr",A80)),ISNUMBER(SEARCH("Lead",A80)),ISNUMBER(SEARCH("Principal",A80))),"Senior",IF(OR(ISNUMBER(SEARCH("Junior",A80)),ISNUMBER(SEARCH("Jr",A80)),ISNUMBER(SEARCH("Entry",A80)),ISNUMBER(SEARCH("Associate",A80))),"Junior",IF(OR(ISNUMBER(SEARCH("Manager",A80)),ISNUMBER(SEARCH("Director",A80)),ISNUMBER(SEARCH("Head",A80)),ISNUMBER(SEARCH("VP",A80))),"Management","Mid-Level"))) -> Mid-Level | C80: =IF(ISNUMBER(SEARCH("Machine Learn",A80)),"ML Engineer",IF(ISNUMBER(SEARCH("Data Engineer",A80)),"Data Engineer",IF(ISNUMBER(SEARCH("Data Analyst",A80)),"Data Analyst",IF(ISNUMBER(SEARCH("Business Analyst",A80)),"Business Analyst",IF(ISNUMBER(SEARCH("Research",A80)),"Research Scientist",IF(ISNUMBER(SEARCH("Manager",A80)),"DS Manager",IF(ISNUMBER(SEARCH("Director",A80)),"Director/VP","Data Scientist"))))))) -> Data Scientist | D80: 3.3 | E80: Chantilly, VA | F80: =IFERROR(LEFT(E80, FIND(",", E80)-1), E80) -> Chantilly | G80: 1001 - 5000 | H80: Aerospace & Defense | I80: 83 | J80: 137 | K80: 110 | L80: =IF(K80<50,"<$50K",IF(K80<75,"$50–75K",IF(K80<100,"$75–100K",IF(K80<125,"$100–125K",IF(K80<150,"$125–150K",">$150K"))))) -> $100–125K | M80: 4
A81: Data Scientist | B81: =IF(OR(ISNUMBER(SEARCH("Senior",A81)),ISNUMBER(SEARCH("Sr",A81)),ISNUMBER(SEARCH("Lead",A81)),ISNUMBER(SEARCH("Principal",A81))),"Senior",IF(OR(ISNUMBER(SEARCH("Junior",A81)),ISNUMBER(SEARCH("Jr",A81)),ISNUMBER(SEARCH("Entry",A81)),ISNUMBER(SEARCH("Associate",A81))),"Junior",IF(OR(ISNUMBER(SEARCH("Manager",A81)),ISNUMBER(SEARCH("Director",A81)),ISNUMBER(SEARCH("Head",A81)),ISNUMBER(SEARCH("VP",A81))),"Management","Mid-Level"))) -> Mid-Level | C81: =IF(ISNUMBER(SEARCH("Machine Learn",A81)),"ML Engineer",IF(ISNUMBER(SEARCH("Data Engineer",A81)),"Data Engineer",IF(ISNUMBER(SEARCH("Data Analyst",A81)),"Data Analyst",IF(ISNUMBER(SEARCH("Business Analyst",A81)),"Business Analyst",IF(ISNUMBER(SEARCH("Research",A81)),"Research Scientist",IF(ISNUMBER(SEARCH("Manager",A81)),"DS Manager",IF(ISNUMBER(SEARCH("Director",A81)),"Director/VP","Data Scientist"))))))) -> Data Scientist | D81: 4.4 | E81: San Jose, CA | F81: =IFERROR(LEFT(E81, FIND(",", E81)-1), E81) -> San Jose | G81: 10000+ | H81: IT Services | I81: 86 | J81: 141 | K81: 113.5 | L81: =IF(K81<50,"<$50K",IF(K81<75,"$50–75K",IF(K81<100,"$75–100K",IF(K81<125,"$100–125K",IF(K81<150,"$125–150K",">$150K"))))) -> $100–125K | M81: 26
...

Sheet RatingScatter
A1: Rating | B1: Avg Salary(K) | C1: Rating Band
A2: 3.8 | B2: 72 | C2: =IF(A2<3,"Under 3.0",IF(A2<3.5,"3.0–3.5",IF(A2<4,"3.5–4.0",IF(A2<4.5,"4.0–4.5","4.5+")))) -> 3.5–4.0
A3: 3.4 | B3: 87.5 | C3: =IF(A3<3,"Under 3.0",IF(A3<3.5,"3.0–3.5",IF(A3<4,"3.5–4.0",IF(A3<4.5,"4.0–4.5","4.5+")))) -> 3.0–3.5
A4: 4.8 | B4: 85 | C4: =IF(A4<3,"Under 3.0",IF(A4<3.5,"3.0–3.5",IF(A4<4,"3.5–4.0",IF(A4<4.5,"4.0–4.5","4.5+")))) -> 4.5+
A5: 3.8 | B5: 76.5 | C5: =IF(A5<3,"Under 3.0",IF(A5<3.5,"3.0–3.5",IF(A5<4,"3.5–4.0",IF(A5<4.5,"4.0–4.5","4.5+")))) -> 3.5–4.0
A6: 2.9 | B6: 114.5 | C6: =IF(A6<3,"Under 3.0",IF(A6<3.5,"3.0–3.5",IF(A6<4,"3.5–4.0",IF(A6<4.5,"4.0–4.5","4.5+")))) -> Under 3.0
A7: 3.4 | B7: 95 | C7: =IF(A7<3,"Under 3.0",IF(A7<3.5,"3.0–3.5",IF(A7<4,"3.5–4.0",IF(A7<4.5,"4.0–4.5","4.5+")))) -> 3.0–3.5
A8: 4.1 | B8: 73.5 | C8: =IF(A8<3,"Under 3.0",IF(A8<3.5,"3.0–3.5",IF(A8<4,"3.5–4.0",IF(A8<4.5,"4.0–4.5","4.5+")))) -> 4.0–4.5
A9: 3.8 | B9: 114 | C9: =IF(A9<3,"Under 3.0",IF(A9<3.5,"3.0–3.5",IF(A9<4,"3.5–4.0",IF(A9<4.5,"4.0–4.5","4.5+")))) -> 3.5–4.0
A10: 3.3 | B10: 61 | C10: =IF(A10<3,"Under 3.0",IF(A10<3.5,"3.0–3.5",IF(A10<4,"3.5–4.0",IF(A10<4.5,"4.0–4.5","4.5+")))) -> 3.0–3.5
A11: 4.6 | B11: 140 | C11: =IF(A11<3,"Under 3.0",IF(A11<3.5,"3.0–3.5",IF(A11<4,"3.5–4.0",IF(A11<4.5,"4.0–4.5","4.5+")))) -> 4.5+
A12: 3.5 | B12: 163.5 | C12: =IF(A12<3,"Under 3.0",IF(A12<3.5,"3.0–3.5",IF(A12<4,"3.5–4.0",IF(A12<4.5,"4.0–4.5","4.5+")))) -> 3.5–4.0
A13: 4.1 | B13: 85 | C13: =IF(A13<3,"Under 3.0",IF(A13<3.5,"3.0–3.5",IF(A13<4,"3.5–4.0",IF(A13<4.5,"4.0–4.5","4.5+")))) -> 4.0–4.5
... A177: 3.3 | B177: 98.5 | C177: =IF(A177<3,"Under 3.0",IF(A177<3.5,"3.0–3.5",IF(A177<4,"3.5–4.0",IF(A177<4.5,"4.0–4.5","4.5+")))) -> 3.0–3.5
A178: -1 | B178: 225
A179: 3.6 | B179: 56.5 | C179: =IF(A179<3,"Under 3.0",IF(A179<3.5,"3.0–3.5",IF(A179<4,"3.5–4.0",IF(A179<4.5,"4.0–4.5","4.5+")))) -> 3.5–4.0
A180: 3.7 | B180: 161.5 | C180: =IF(A180<3,"Under 3.0",IF(A180<3.5,"3.0–3.5",IF(A180<4,"3.5–4.0",IF(A180<4.5,"4.0–4.5","4.5+")))) -> 3.5–4.0
A181: 3.4 | B181: 147 | C181: =IF(A181<3,"Under 3.0",IF(A181<3.5,"3.0–3.5",IF(A181<4,"3.5–4.0",IF(A181<4.5,"4.0–4.5","4.5+")))) -> 3.0–3.5
A182: 4.1 | B182: 61 | C182: =IF(A182<3,"Under 3.0",IF(A182<3.5,"3.0–3.5",IF(A182<4,"3.5–4.0",IF(A182<4.5,"4.0–4.5","4.5+")))) -> 4.0–4.5
A183: 2.6 | B183: 120 | C183: =IF(A183<3,"Under 3.0",IF(A183<3.5,"3.0–3.5",IF(A183<4,"3.5–4.0",IF(A183<4.5,"4.0–4.5","4.5+")))) -> Under 3.0
A184: 3.2 | B184: 124.5 | C184: =IF(A184<3,"Under 3.0",IF(A184<3.5,"3.0–3.5",IF(A184<4,"3.5–4.0",IF(A184<4.5,"4.0–4.5","4.5+")))) -> 3.0–3.5
A185: 3.9 | B185: 148 | C185: =IF(A185<3,"Under 3.0",IF(A185<3.5,"3.0–3.5",IF(A185<4,"3.5–4.0",IF(A185<4.5,"4.0–4.5","4.5+")))) -> 3.5–4.0
A186: 4.7 | B186: 59 | C186: =IF(A186<3,"Under 3.0",IF(A186<3.5,"3.0–3.5",IF(A186<4,"3.5–4.0",IF(A186<4.5,"4.0–4.5","4.5+")))) -> 4.5+
A187: 3.7 | B187: 146.5 | C187: =IF(A187<3,"Under 3.0",IF(A187<3.5,"3.0–3.5",IF(A187<4,"3.5–4.0",IF(A187<4.5,"4.0–4.5","4.5+")))) -> 3.5–4.0
A188: 2.9 | B188: 91.5 | C188: =IF(A188<3,"Under 3.0",IF(A188<3.5,"3.0–3.5",IF(A188<4,"3.5–4.0",IF(A188<4.5,"4.0–4.5","4.5+")))) -> Under 3.0
A189: 3 | B189: 133 | C189: =IF(A189<3,"Under 3.0",IF(A189<3.5,"3.0–3.5",IF(A189<4,"3.5–4.0",IF(A189<4.5,"4.0–4.5","4.5+")))) -> 3.0–3.5
A190: 4.7 | B190: 140.5 | C190: =IF(A190<3,"Under 3.0",IF(A190<3.5,"3.0–3.5",IF(A190<4,"3.5–4.0",IF(A190<4.5,"4.0–4.5","4.5+")))) -> 4.5+
... A267: 3.5 | B267: 96 | C267: =IF(A267<3,"Under 3.0",IF(A267<3.5,"3.0–3.5",IF(A267<4,"3.5–4.0",IF(A267<4.5,"4.0–4.5","4.5+")))) -> 3.5–4.0
A268: -1 | B268: 225
A269: 3.2 | B269: 101 | C269: =IF(A269<3,"Under 3.0",IF(A269<3.5,"3.0–3.5",IF(A269<4,"3.5–4.0",IF(A269<4.5,"4.0–4.5","4.5+")))) -> 3.0–3.5
A270: 3.3 | B270: 98.5 | C270: =IF(A270<3,"Under 3.0",IF(A270<3.5,"3.0–3.5",IF(A270<4,"3.5–4.0",IF(A270<4.5,"4.0–4.5","4.5+")))) -> 3.0–3.5
A271: 3.9 | B271: 77.5 | C271: =IF(A271<3,"Under 3.0",IF(A271<3.5,"3.0–3.5",IF(A271<4,"3.5–4.0",IF(A271<4.5,"4.0–4.5","4.5+")))) -> 3.5–4.0
A272: 3.7 | B272: 161.5 | C272: =IF(A272<3,"Under 3.0",IF(A272<3.5,"3.0–3.5",IF(A272<4,"3.5–4.0",IF(A272<4.5,"4.0–4.5","4.5+")))) -> 3.5–4.0
A273: 3.6 | B273: 56.5 | C273: =IF(A273<3,"Under 3.0",IF(A273<3.5,"3.0–3.5",IF(A273<4,"3.5–4.0",IF(A273<4.5,"4.0–4.5","4.5+")))) -> 3.5–4.0
A274: 3.4 | B274: 147 | C274: =IF(A274<3,"Under 3.0",IF(A274<3.5,"3.0–3.5",IF(A274<4,"3.5–4.0",IF(A274<4.5,"4.0–4.5","4.5+")))) -> 3.0–3.5
A275: 3.5 | B275: 90 | C275: =IF(A275<3,"Under 3.0",IF(A275<3.5,"3.0–3.5",IF(A275<4,"3.5–4.0",IF(A275<4.5,"4.0–4.5","4.5+")))) -> 3.5–4.0
A276: 4.3 | B276: 58 | C276: =IF(A276<3,"Under 3.0",IF(A276<3.5,"3.0–3.5",IF(A276<4,"3.5–4.0",IF(A276<4.5,"4.0–4.5","4.5+")))) -> 4.0–4.5
A277: 4.1 | B277: 61 | C277: =IF(A277<3,"Under 3.0",IF(A277<3.5,"3.0–3.5",IF(A277<4,"3.5–4.0",IF(A277<4.5,"4.0–4.5","4.5+")))) -> 4.0–4.5
A278: 2.6 | B278: 120 | C278: =IF(A278<3,"Under 3.0",IF(A278<3.5,"3.0–3.5",IF(A278<4,"3.5–4.0",IF(A278<4.5,"4.0–4.5","4.5+")))) -> Under 3.0
A279: 3.6 | B279: 128 | C279: =IF(A279<3,"Under 3.0",IF(A279<3.5,"3.0–3.5",IF(A279<4,"3.5–4.0",IF(A279<4.5,"4.0–4.5","4.5+")))) -> 3.5–4.0
...

Sheet SizeRating
A3: Row Labels | B3: Average of Rating
A4: 51 - 200 | B4: 4.0212766
A5: 18264 | B5: 3.7354839
A6: 201 - 500 | B6: 3.6700855
A7: 10000+ | B7: 3.63
A8: 1001 - 5000 | B8: 3.5986667
A9: 501 - 1000 | B9: 3.5813433
A10: 5001 - 10000 | B10: 3.5315789
A11: unknown | B11: 0.2
A12: Grand Total | B12: 3.6188679

Sheet Size
B3: Values
A4: Row Labels | B4: Average of Avg Salary(K) | C4: Average of Lower Salary(in K) | D4: Average of Upper Salary(in K ) | E4: Count of Job Title
A5: 1001 - 5000 | B5: 94.69 | C5: 68.953333 | D5: 120.42667 | E5: 150
A6: 501 - 1000 | B6: 91.503731 | C6: 66.865672 | D6: 116.14179 | E6: 134
A7: 10000+ | B7: 112.80385 | C7: 83.661538 | D7: 141.94615 | E7: 130
A8: 201 - 500 | B8: 100.24786 | C8: 72.136752 | D8: 128.35897 | E8: 117
A9: 51 - 200 | B9: 111.77128 | C9: 84.468085 | D9: 139.07447 | E9: 94
A10: 5001 - 10000 | B10: 97.486842 | C10: 70.421053 | D10: 124.55263 | E10: 76
A11: 18264 | B11: 105.06452 | C11: 78.580645 | D11: 131.54839 | E11: 31
A12: unknown | B12: 127.05 | C12: 112.1 | D12: 142 | E12: 10
A13: Grand Total | B13: 101.4845 | C13: 74.754717 | D13: 128.21429 | E13: 742

Sheet Industry
A1: Size | B1: (All)
A2: Exp Level | B2: (All)
B4: Values
A5: Row Labels | B5: Average of Avg Salary(K) | C5: Count of Job Title
A6: Other Retail Stores | B6: 163.5 | C6: 1
A7: Motion Picture Production & Distribution | B7: 146 | C7: 1
A8: Financial Analytics & Research | B8: 145.125 | C8: 8
A9: Health, Beauty, & Fitness | B9: 139.5 | C9: 1
A10: Telecommunications Services | B10: 131.5 | C10: 4
A11: Brokerage Services | B11: 129 | C11: 2
A12: Auctions & Galleries | B12: 128 | C12: 1
A13: Internet | B13: 123.81034 | C13: 29
A14: Investment Banking & Asset Management | B14: 118.4 | C14: 5
A15: TV Broadcast & Cable Networks | B15: 117.75 | C15: 2
A16: Enterprise Software & Network Solutions | B16: 115.36905 | C16: 42
A17: Computer Hardware & Software | B17: 115.19492 | C17: 59
A18: -1 | B18: 114.65 | C18: 10
A19: Accounting | B19: 113.5 | C19: 1
A20: Biotech & Pharmaceuticals | B20: 112.12054 | C20: 112
A21: Grand Total | B21: 116.54496 | C21: 278

Sheet City Salary
A1: Size | B1: (Multiple Items)
A2: Exp Level | B2: (All)
A4: Row Labels | B4: Average of Avg Salary(K)
A5: San Francisco | B5: 175.75
A6: Jersey City | B6: 173
A7: Mountain View | B7: 172.5
A8: Novato | B8: 168
A9: San Jose | B9: 163.5
A10: Santa Clara | B10: 154.5
A11: Marlborough | B11: 150.7
A12: Newark | B12: 146
A13: Fort Lee | B13: 145.66667
A14: Natick | B14: 139.5
A15: Palo Alto | B15: 135.33333
A16: Herndon | B16: 131.75
... A20: Grand Total | B20: 146.3

Sheet CityCount
A1: Industry | B1: (All)
A3: Row Labels | B3: Count of Job Title
A4: New York | B4: 55
A5: San Francisco | B5: 49
A6: Cambridge | B6: 48
A7: Chicago | B7: 32
A8: Boston | B8: 23
A9: San Jose | B9: 13
A10: Pittsburgh | B10: 12 | K10: Row Labels | L10: Count of Count of Job Title2
A11: Rockville | B11: 11 | K11: Boston | L11: 1
A12: Washington | B12: 11 | K12: Cambridge | L12: 1
A13: Springfield | B13: 10 | K13: Chicago | L13: 1
A14: Winston-Salem | B14: 10 | K14: Grand Total | L14: 1
A15: Herndon | B15: 10 | K15: Herndon | L15: 1
A16: Richland | B16: 10 | K16: Indianapolis | L16: 1
A17: Indianapolis | B17: 9 | K17: New York | L17: 1
A18: San Diego | B18: 9 | K18: Pittsburgh | L18: 1
A19: Grand Total | B19: 312 | K19: Richland | L19: 1
K20: Rockville | L20: 1
K21: San Diego | L21: 1
K22: San Francisco | L22: 1
K23: San Jose | L23: 1
K24: Springfield | L24: 1
K25: Washington | L25: 1
K26: Winston-Salem | L26: 1
K27: Grand Total | L27: 16

Sheet Title Count
A1: Exp Level | B1: (All)
A3: Row Labels | B3: Count of Job Title
A4: Data Scientist | B4: 435
A5: Data Engineer | B5: 119
A6: Data Analyst | B6: 99
A7: ML Engineer | B7: 29
A8: DS Manager | B8: 25
A9: Research Scientist | B9: 21
A10: Director/VP | B10: 14
A11: Grand Total | B11: 742

Sheet Title Salary
A1: Exp Level | B1: (Multiple Items)
B3: Values
A4: Row Labels | B4: Average of Upper Salary(in K ) | C4: Average of Lower Salary(in K) | D4: Average of Avg Salary(K)
A5: Data Analyst | B5: 85.688889 | C5: 47.588889 | D5: 66.638889
A6: Data Engineer | B6: 133.89474 | C6: 75.72807 | D6: 104.8114
A7: Data Scientist | B7: 134.12322 | C7: 80.035545 | D7: 107.07938
A8: DS Manager | B8: 210 | C8: 125 | D8: 167.5
A9: ML Engineer | B9: 156.18519 | C9: 87.666667 | D9: 121.92593
A10: Research Scientist | B10: 118.05 | C10: 66.5 | D10: 92.275
A11: Grand Total | B11: 128.25778 | C11: 75.019259 | D11: 101.63852

Sheet Rating Band
A1: Rating Band | B1: Avg Salary(K) | C1: Job Title | E1: Values
A2: 3.5–4.0 | B2: 72 | C2: Data Scientist | D2: Row Labels | E2: Average of Avg Salary(K) | F2: Count of Job Title
A3: 3.0–3.5 | B3: 87.5 | C3: Healthcare Data Scientist | D3: Under 3.0 | E3: 87.673611 | F3: 72
A4: 4.5+ | B4: 85 | C4: Data Scientist | D4: 3.0–3.5 | E4: 97.10625 | F4: 160
A5: 3.5–4.0 | B5: 76.5 | C5: Data Scientist | D5: 3.5–4.0 | E5: 102.89107 | F5: 280
A6: Under 3.0 | B6: 114.5 | C6: Data Scientist | D6: 4.0–4.5 | E6: 106.55096 | F6: 157
A7: 3.0–3.5 | B7: 95 | C7: Data Scientist | D7: 4.5+ | E7: 103.48387 | F7: 62
A8: 4.0–4.5 | B8: 73.5 | C8: Data Scientist | D8: Grand Total | E8: 100.96238 | F8: 731
A9: 3.5–4.0 | B9: 114 | C9: Data Scientist
A10: 3.0–3.5 | B10: 61 | C10: Research Scientist
A11: 4.5+ | B11: 140 | C11: Data Scientist
A12: 3.5–4.0 | B12: 163.5 | C12: Data Scientist
A13: 4.0–4.5 | B13: 85 | C13: Data Scientist
A14: 3.0–3.5 | B14: 139 | C14: Staff Data Scientist - Technology
A15: 4.0–4.5 | B15: 65.5 | C15: Data Analyst
A16: 3.5–4.0 | B16: 113.5 | C16: Data Scientist
A17: 3.5–4.0 | B17: 146 | C17: Data Engineer I
A18: 3.5–4.0 | B18: 102 | C18: Scientist I/II, Biology
A19: 4.0–4.5 | B19: 153.5 | C19: Customer Data Scientist
A20: 4.0–4.5 | B20: 142.5 | C20: Data Scientist - Health Data Analytics
... A732: 3.5–4.0 | B732: 93.5 | C732: Research Scientist, Immunology - Cancer Biology
C733: IT - Data Engineer II
C734: Machine Learning Engineer (NLP)
